Workbook

Sheet AMJ QOP
A1: Bucket | B1: Sub Bucket | C1: Quarterly Goals | D1: May
A3: Media
A4: Brand | B4: Campaigns | C4: 5k Subscriptions + Brand Campaign: AI Shift, The Checkout | D4: 1k Subscriptions + Brand Campaign: AI Shift, The Checkout
C5: 5k Registration, Datalabs Free Brand Campaign | D5: 1k+ Registrations
C6: 2k Downloads/Registrations on Reports (Ecom + Upcoming + Existing) | D6: 1k+ Downloads/Registrations on Ecommerce Report
C7: Inc42 Positioning - Update all brand touchpoints with updated positioning
C8: AI Content + Brand Amplifaction, 50k interactions/month | D8: Amplify AI content on social, 25k interactions on social
A10: Social | C10: 600K+ Monthly Interactions ORM | D10: 400k Monthly Interactions Amplify AI content on social, 25k interactions on social 2 New Marketing-Led Formats
A12: Video | C12: 5 Mn+ Video Views & 100k Interactions Per Month AI Operator: 3-4 Videos/Week, 500k+ Views & 10k+ Interactions Event-Led Video Pipeline: 4-5 Videos/Week, 1Mn+ Views & 20k+ Interactions 2 Original Short (1-2 min) Formats (Story-Led, News Roundup): 3-4 Videos/Week, 1Mn+ Views & 20k+ Interactions 1 Youtube (10-15 min) Format (2 Videos/Week + 5 Reels/Week): 2Mn+ Views & 40k+ Interactions | D12: AI Operator: 3-4 Videos/Week, 500k+ Views & 10k+ Interactions Event-Led Video Pipeline: 3-4 Videos/Week, 1Mn+ Views & 20k+ Interaction 1 Original Short (1-2 min) Formats (Story-Led or News Roundup): 3-4 Videos/Week, 1Mn+ Views & 20k+ Interactions
A14: Marketing | B14: Acquisition & Growth | C14: WEIU (NS2) Funnel Optimisation & CRO for Onsite Registration Growth Onboarding & CLM Systems | D14: Establish Reporting for WEIU & complete funnel Lock & deploy onboarding & CLM for Inc42 & Datalabs Establish impact of campaigns & CLM on funnel + set goals for June
B15: Product | C15: Datalabs SEO/AEO Expansion Global Search v2 Unified Inc42+DL Experience Report Pages Revamp Inc42 App | D15: Datalabs SEO/AEO Expansion Report Pages Revamp Deploy Inc42 App v1 Global Search v2
B16: Data | C16: 95% DCI, DFI, DAI for all Funded Companies 500 Trend Based & High Value Early Stage Startups Adding 1k New Investors [From the existing DB] Social Intelligence Data Semantic Data Data Warehouse + Unified User Data with Reverse-ETL | D16: 95% DCI, DFI, DAI for all X Funded Companies 500 Trend Based & High Value Early Stage Startups Adding 1k New Investors [From the existing DB] Social Intelligence Data v1 Data Warehouse + Unified User Data with Reverse-ETL Phase 1
B17: Infra & Systems | C17: Reporting Dashboards, Automated Reporting + Insights for Media, DL, EFL & IPs Streamline Asana SOP Updates Automate Newsletters AI-Led Systems for IP Marketing AI-Led + HIL Customer Support via Freshdesk/Hubspot Analytics & Instrumentation Audit Internal AI Tools & Systems: News AI 2.0, Markets AI 2.0, AI Data Requests, AI Research on Inc42 Data | D17: Reporting Dashboards, Automated Reporting + Insights for Media, DL, EFL & IPs Streamline Asana Analytics & Instrumentation Audit Internal AI Tools & Systems: News AI 2.0, Markets AI 2.0, AI Data Requests, AI Research on Inc42 Data
A19: BrandLabs Marketing | B19: Brandlabs Campaigns Delivery | C19: On Time Delivery, Campaign Metrics, Organic vs Inorganic Split, Budget Saved
B20: Client Pipeline Influenced | C20: MQLs (New, Returning) Inbound Marketing System
B21: Brand | C21: BL Rebranding + Website BL Newsletter NPS Tracking
A23: IPs | B23: AI Summit | C23: 1000+ ticket sales. 60%+ selection rate. 600 attendees. | D23: 1000+ ticket sales. 60%+ selection rate. 600 attendees.
B24: AmplifAI | C24: 150+ applications. 5 startups selected. Demo day at AI Summit. | D24: 150+ applications. 5 startups selected. Demo day at AI Summit.
B25: D2CX Runway | C25: 100+ applications, 15 shortlisted for Pitches 2nd Edition | D25: 100+ applications, 15 shortlisted for Pitches 2nd Edition
B26: D2CX Converge | C26: Editions TBD
B27: D2C Summit | C27: 150 ticket sales, 50% selection rate | D27: Complete pre-reg campaign, launch Phase 1 marketing & achieve 75 ticket sales
B28: D2C Retreat | C28: Launch D2C Retreat 2026
B29: AI Workplaces | C29: Lock Concept & Prep for Launch

Sheet May MOP
A1: Area | B1: Bucket | C1: Sub Bucket | D1: Goals | E1: Accountability | F1: Consulted | G1: Deadline | H1: Divisions Involved | I1: Team Members Involved | J1: Completion Status | K1: Progress (%) | L1: Bottlenecks/Comments | N1: 11 May - 17 May | O1: 18 May - 24 May | P1: 25 May - 31 May
A2: IPs | B2: IPs
B3: AI Summit | D3: 1000+ ticket sales · 60%+ selection rate · 600 attendees | E3: Vishvani | F3: Utkarsh | G3: 46169 | H3: Marketing, Editorial, Sales | I3: Vishvani, Bhavika, Amit | J3: Completed | K3: 0.857 | N3: 200 ticket sales | O3: 250 ticket sales | P3: 125 ticket sales
B4: AmplifAI | D4: 150+ applications · 5 startups selected · Demo day at AI Summit | E4: Saumya | F4: Utkarsh | G4: 46153 | H4: Marketing, BL | I4: Saumya, Bhavika | J4: Completed | K4: 1 | N4: - | O4: - | P4: -
B5: D2C Summit | D5: Complete pre-reg campaign · 150 ticket sales | E5: Nityam | F5: Utkarsh, Pooja | G5: 46173 | H5: Marketing, Editorial | I5: Nityam, Animesh | J5: In Progress | K5: 0.4 | L5: 58 tickets sold as of 31st may | N5: Launch pre-reg campaign 50 Ticket Sales | O5: 50 Ticket Sales Prep for Phase 1 Marketing | P5: 50 Ticket Sales Phase 1 Marketing Ready To Launch
B6: D2CX Runway | D6: 100+ applications · 15 shortlisted for Pitches · 2nd Edition kickoff | E6: Nityam | F6: Utkarsh, Pooja | G6: 46173 | H6: Marketing, BL | I6: Nityam, Animesh | J6: Completed | K6: 1 | L6: completed | N6: - | O6: - | P6: TBD
B7: D2CX Converge | D7: Launch Season 2 Marketing | E7: Arminder | F7: Utkarsh, Pooja | G7: 46173 | H7: Marketing, BL | I7: Arminder | J7: Delayed | K7: 0 | N7: - | O7: Prep For Launch | P7: Launch Season 2 Marketing
A9: Media | B9: Media
B10: Social | C10: Inc42 Social Growth | D10: 400K monthly interactions · 2 new marketing-led formats | E10: Arminder | F10: Utkarsh, Pooja | G10: 46173 | H10: Marketing, Design | I10: Arminder, Tanya, Ananya | J10: In Progress | K10: 0.75 | L10: 400K monthly interactions numbers achieved with 330.5K quality engagements, Finalised new carousel format, Marketing Format: Picking up various Industries from datalabs, working on report recurring task, New superhero templates for Check out newsletter | N10: Social media reporting locked & automated 2 new carousal templates 1 new marketing-led format | O10: 3 New Superhero Templates/Formats | P10: 1 new marketing-led format
B11: Social | C11: AI Content Amplification | D11: Amplify AI content on social (25K interactions on social) | E11: Arminder | F11: Utkarsh, Pooja | G11: 46173 | H11: Marketing, Editorial | I11: Arminder, Tanya, Ananya | J11: Completed | K11: 1 | N11: Reporting Locked AI Summit Superheroes | O11: AI Summit Superheroes Ongoing | P11: AI Summit Superheroes Ongoing
B12: Newsletters | C12: AI Shift, The Checkout, Daily Brief | D12: 1K subscriptions · Brand Campaign | E12: Nityam | F12: Utkarsh | G12: 46173 | H12: Marketing, Editorial | I12: Nityam, Animesh | J12: In Progress | K12: 0.2 | L12: Plan made, execution yet to start | N12: Reporting Locked Marketing Plan Locked | O12: AI Shift + Checkout Marketing Campaign Launch | P12: 1K+ Subscriptions
B13: Acquisition | C13: Acquisition + WEIU (NS2) | D13: Establish reporting for WEIU & complete funnel · Lock & deploy onboarding & CLM for Inc42 & Datalabs · Establish impact of campaigns & CLM on funnel + set goals for June | E13: Nityam | F13: Utkarsh, Tech | G13: 46173 | H13: Marketing, Tech | I13: Nityam, Animesh, Prapti | J13: In Progress | K13: 0.7 | L13: planning and reporting done, yet to deploy | N13: Customer.io Hygiene/Setup + Properties + Tag/Segment Taxonomy Locked WEIU Reporting Locked Onsite Optins Optimisation Plan | O13: Onsite Optins Optimisation Deployed L2 7-day onboarding sequence launched | P13: L3 source-aware sequences launched
B14: Datalabs | C14: Datalabs Free Launch — Activation | D14: 1K+ registrations · Activation campaigns | E14: Nityam | F14: Utkarsh, Tech | G14: 46173 | H14: Marketing, Datalabs | I14: Bhavika, Prapti | J14: Delayed | K14: 0 | L14: yet to start | N14: Context + Reporting + Master Messaging Doc | O14: Marketing Plan + Common Messaging Doc + Assets | P14: 1K+ Registrations
B15: Video | C15: AI Operator | D15: 3-4 videos/week · 500K+ views & 10K+ interactions | E15: Tejas | F15: Utkarsh, Pooja | G15: 46173 | H15: Video, Marketing | I15: Tejas, Aditya, Video Team | J15: Delayed | K15: 0 | N15: v2 Concept Note on Video Types & Scripts | O15: 4 Videos Published | P15: 4 Videos Published
B16: Video | C16: Event-Led Pipeline | D16: 3-4 videos/week · 1Mn+ views & 20K+ interactions | E16: Aditya | F16: Utkarsh, Pooja | G16: 46173 | H16: Video, Marketing | I16: Tejas, Aditya, Video Team | J16: In Progress | K16: 0.1 | N16: Video Reporting Locked & Automated | O16: AI Summit Shoot Plan Locked (Series + Distribution-First Approach)
B17: Video | C17: Original Short Format | D17: 1 Original Short (1-2 min) format – Story-Led or News Roundup | E17: Tejas, Aditya | F17: Utkarsh, Pooja | G17: 46173 | H17: Video, Marketing | I17: Tejas, Aditya, Video Team | J17: Delayed | K17: 0 | N17: - | O17: - | P17: -
B18: Product | C18: Datalabs SEO/AEO Expansion | D18: Phase 1 SEO & AEO changes: Meta Tags Fixes, SSR -> CSR, Schema markups, Rel-Canonical changes | E18: Alistin, Ashish | F18: Utkarsh | G18: 46173 | H18: Tech, Marketing | I18: Tech, Data | J18: Completed | K18: 1 | N18: Phase 1 SEO & AEO changes: Meta Tags Fixes, SSR -> CSR, Schema markups, Rel-Canonical changes | O18: Phase 1 + Phase 2 Review + Fixes | P18: Phase 3 Plan + Kickoff
B19: Product | C19: Report Pages Revamp + Global Search v2 | D19: Report Pages Revamp (new template live) · Global Search v2 Launched | E19: Alistin, Ashish | F19: Utkarsh | G19: 46173 | H19: Tech, Marketing | I19: Tech, Data | J19: In Progress | K19: 0.8 | L19: Global Search is live, We are working on report page, which will be completed by 2nd June | N19: - | O19: Report Pages Revamp (new template live) · Global Search v2 Launched | P19: -
B20: Product | C20: Inc42 App v1 | D20: Deploy Inc42 App v1 | E20: Alistin, Ashish | F20: Utkarsh | G20: 46173 | H20: Tech, Marketing | I20: Tech | J20: In Progress | K20: 0.3 | L20: Design is still ongoing, dev isn't started yet. | N20: Lock concept note, PRD, scoping, feasibility & mapping | O20: Alpha Version Scoping Locked + Build Starts | P20: Alpha Version Ready, Testing, Prep for Launch
B21: Data | C21: DCI / DFI / DAI Quality | D21: 95% DCI/DFI/DAI for funded companies | E21: Prapti | F21: Utkarsh, Tech | G21: 46173 | H21: Tech, Data | I21: Tech, Prapti, Data Team | J21: Completed | K21: 1 | N21: TBD | O21: TBD | P21: TBD
B22: Data | C22: Trend-Based Early-Stage Startups | D22: 500 trend-based & high-value early-stage startups added | E22: Prapti | F22: Utkarsh, Tech | G22: 46173 | H22: Tech, Data | I22: Tech, Prapti, Data Team | J22: Completed | K22: 1 | N22: TBD | O22: TBD | P22: TBD
B23: Data | C23: Investor Database Expansion | D23: 1K new investors from existing DB | E23: Prapti | F23: Utkarsh, Tech | G23: 46173 | H23: Tech, Data | I23: Tech, Prapti, Data Team | J23: Delayed | K23: 0 | N23: TBD | O23: TBD | P23: TBD
B24: Data | C24: Social Intelligence Data v1 | D24: Social Intelligence Data v1 — pipeline ingestion live | E24: Prapti | F24: Utkarsh, Tech | G24: 46173 | H24: Tech, Data | I24: Tech, Prapti, Data Team | J24: In Progress | K24: 0.6 | L24: Have checked Linkedin Sales Nav from feasibility pov, now need to create pipelines | N24: Scoping Locked | O24: TBD | P24: TBD
B25: Data | C25: Data Warehouse | D25: Data Warehouse + Unified User Data with Reverse-ETL — Phase 1 | E25: Prapti | F25: Utkarsh, Tech | G25: 46173 | H25: Tech, Data | I25: Tech, Prapti, Data Team | J25: In Progress | K25: 0.7 | L25: Need to pick reverse ETL | N25: TBD | O25: TBD | P25: TBD
B26: Infra | C26: Reporting Dashboards + Automated Reporting | D26: Reporting Dashboards · Automated Reporting + Insights for Social, Video, Media, DL, EFL & IPs | E26: Prapti | F26: Utkarsh, Tech, Nityam | G26: 46173 | H26: Marketing, Tech, Data | I26: Tech, Data | J26: Yet To Start | K26: 0 | N26: Scoping Locked | O26: TBD | P26: TBD
B27: Infra | C27: Internal AI Tools — AI Data Requests + AI Research | D27: AI Data Requests pilot + AI Research on Inc42 Data pilot | E27: Prapti | F27: Utkarsh, Tech | G27: 46173 | H27: Tech, Data, Editorial | I27: Tech, Data | J27: Delayed | K27: 0 | N27: - | O27: - | P27: Scoping Locked
B28: Infra | C28: Analytics & Instrumentation Audit | D28: GA4 + PostHog + Customer.io audit & fixes | E28: Alistin | F28: Utkarsh, Tech | G28: 46173 | H28: Marketing, Tech | I28: Marketing, Tech | J28: In Progress | K28: 0.4 | N28: GA4 + PostHog + Customer.io audit & fixes | O28: GA4 + PostHog + Customer.io audit & fixes | P28: -
B29: Infra | C29: Internal AI Tools — News AI 2.0 + Markets AI 2.0 | D29: News AI 2.0, Markets AI 2.0 → production (in editorial newsroom) | E29: Ashish | F29: Utkarsh, Pooja | G29: 46173 | H29: Tech, Editorial | I29: Tech, Data | J29: On Track | K29: 0.75 | N29: Deploy to Editors + Feedback loop + Improvements | O29: Deploy to Editorial Team | P29: Feedback loop + Improvements

Sheet June MOP
A1: Area | B1: Bucket | C1: Sub Bucket | D1: Goals | E1: Accountability | F1: Consulted | G1: Deadline | H1: Divisions Involved | I1: Team Members Involved | J1: Completion Status | K1: Progress (%) | L1: Bottlenecks/Comments
A2: IPs | B2: IPs
B3: D2C Summit | D3: Complete pre-reg campaign · 300 ticket sales | E3: Vishvani | F3: Utkarsh, Pooja | H3: Marketing, Editorial | I3: Nityam, Bhavika | J3: On Track | K3: 0.77 | L3: 232
B4: D2CX Runway | D4: 100+ applications · 15 shortlisted for Pitches · 2nd Edition kickoff | E4: Nityam | F4: Utkarsh, Pooja | H4: Marketing, BL | I4: Nityam, Bhavika | J4: Completed | K4: 1
B5: D2CX Converge | D5: Launch Season 2 Marketing | E5: Arminder | F5: Utkarsh, Pooja | H5: Marketing, BL | I5: Arminder | J5: Completed | K5: 1
B6: D2CX Retreat | D6: Prep for Launch | J6: Delayed
B7: IP Infra | D7: AI-Led Systems for IP Marketing | E7: Nityam | J7: Yet To Start | K7: 0
A9: Media | B9: Media
B10: Social | C10: Inc42 Social Growth | D10: 200K monthly interactions · 2 new marketing-led formats | E10: Arminder | F10: Utkarsh, Pooja | H10: Marketing, Design | I10: Arminder, Tanya, Ananya | J10: Completed | K10: 0.97 | L10: 194K numbers achieved, Finaised 3 new carousel formats (design wise)
B11: Social | C11: AI Content Amplification | D11: AI content on social (25K interactions on social) | E11: Arminder | F11: Utkarsh, Pooja | H11: Marketing, Editorial | I11: Arminder, Tanya, Ananya | J11: Completed
B12: Newsletters | C12: AI Shift, The Checkout, Daily Brief | D12: 2.5K subscriptions · Brand Campaign | E12: Nityam | F12: Utkarsh | H12: Marketing, Editorial | I12: Nityam, Animesh | J12: Yet To Start | K12: 0 | L12: Depriotised
B13: Acquisition | C13: Acquisition + WEIU (NS2) | D13: Establish reporting for WEIU & complete funnel · Lock & deploy onboarding & CLM for Inc42 & Datalabs · Establish impact of campaigns & CLM on funnel + set goals for June | E13: Nityam | F13: Utkarsh, Tech | H13: Marketing, Tech | I13: Nityam, Animesh, Prapti | J13: Delayed | K13: 0.3 | L13: Pending on Design front
B14: Datalabs | C14: Datalabs Free Launch — Activation | D14: 2.5K+ registrations · Activation campaigns | E14: Nityam | F14: Utkarsh, Tech | H14: Marketing, Datalabs | I14: Bhavika, Animesh, Prapti | J14: In Progress | K14: 0.2
B15: Video | C15: Event-Led Pipeline | D15: 3-4 videos/week · 1Mn+ views & 20K+ interactions | E15: Aditya | F15: Utkarsh, Pooja | H15: Video, Marketing | I15: Tejas, Aditya, Video Team | J15: In Progress | K15: 0.5
B16: Video | C16: Original Short Format | D16: 1 Original Short (1-2 min) format – Story-Led or News Roundup | E16: Aditya | F16: Utkarsh, Pooja | H16: Video, Marketing | I16: Tejas, Aditya, Video Team | J16: Yet To Start | K16: 0.5
B17: Reports | C17: Ecommerce Report | D17: 1K+ downloads/registrations on Reports | E17: Arminder | F17: Utkarsh, Pooja | H17: Research, Marketing | I17: Sandeep, Arminder, Animesh | J17: On Track | K17: 0.74 | L17: 735 downloads
B18: Product | C18: Datalabs SEO/AEO Expansion | D18: Audit & Improve SEO/AEO for Datalabs | E18: Ashish, Prapti | F18: Utkarsh | H18: Tech, Marketing | I18: Tech, Data | J18: Completed | K18: 1
B19: Product | C19: Report Pages Revamp + Global Search v2 | D19: Report Pages Revamp (new template live) | E19: Alistin, Ashish | F19: Utkarsh | H19: Tech, Marketing | I19: Tech, Data | J19: Completed | K19: 1
B20: Product | C20: Inc42 App v1 | D20: Deploy Inc42 App v1 | E20: Alistin, Ashish | F20: Utkarsh | H20: Tech, Marketing | I20: Tech | J20: Delayed | K20: 0.5
B21: Data | C21: DCI / DFI / DAI Quality | D21: 95% DCI/DFI/DAI for funded companies | E21: Prapti | F21: Utkarsh, Tech | H21: Tech, Data | I21: Tech, Prapti, Data Team | J21: On Track | K21: 1 | L21: Completed this month's target
B22: Data | C22: Trend-Based Early-Stage Startups | D22: 500 trend-based & high-value early-stage startups added | E22: Prapti | F22: Utkarsh, Tech | H22: Tech, Data | I22: Tech, Prapti, Data Team | J22: Completed | K22: 1
B23: Data | C23: Investor Database Expansion | D23: 1K new investors from existing DB | E23: Prapti | F23: Utkarsh, Tech | H23: Tech, Data | I23: Tech, Prapti, Data Team | J23: Delayed
B24: Data | C24: Social Intelligence Data v1 | D24: Social Intelligence Data v1 — pipeline live | E24: Prapti | F24: Utkarsh, Tech | H24: Tech, Data | I24: Tech, Prapti, Data Team | J24: Completed | K24: 1
B25: Data | C25: Social Intelligence Data | D25: Internal AI Use cases 1. Editorial & Social Content Suggestions 2. Make Social Intelligence Data Queryable | E25: Prapti | F25: Utkarsh | H25: Data, Tech | I25: Data Team, Tech | J25: On Track | K25: 0.8
B26: Data | C26: Data Warehouse | D26: Data Warehouse + Unified User Data with Reverse-ETL — Phase 2 | E26: Prapti | F26: Utkarsh, Tech | H26: Tech, Data | I26: Tech, Prapti, Data Team | J26: On Track | K26: 0.8
B27: Infra | C27: Reporting Dashboards + Automated Reporting | D27: Reporting Dashboards · Automated Reporting + Insights for Social, Video, Media, DL, EFL & IPs | E27: Prapti | F27: Utkarsh, Tech, Nityam | H27: Marketing, Tech, Data | I27: Tech, Data | J27: Yet To Start
B28: Infra | C28: Internal AI Tools — AI Data Requests + AI Research | D28: AI Data Requests pilot + AI Research on Inc42 Data pilot | E28: Prapti | F28: Utkarsh, Tech | H28: Tech, Data, Editorial | I28: Tech, Data | J28: Yet To Start
B29: Infra | C29: Analytics & Instrumentation Audit | D29: GA4 + PostHog + Customer.io audit & fixes | E29: Animesh | F29: Utkarsh, Tech | H29: Marketing, Tech | I29: Marketing, Tech | J29: In Progress | K29: 0.2
B30: Infra | C30: Newsletters | D30: Automate All Weekly Newsletters | E30: Animesh | F30: Utkarsh, Tech, Nityam | H30: Tech, Editorial | I30: Tech, Data | J30: On Track | K30: 0.8 | L30: Markets Newsletter is Automated

Sheet July MOP
A1: Area | B1: Bucket | C1: Sub Bucket | D1: Goals | E1: Accountability | F1: Consulted | G1: Deadline | H1: Divisions Involved | I1: Team Members Involved | J1: Completion Status | K1: Progress (%) | L1: Bottlenecks/Comments
A2: IPs | B2: IPs
B3: D2C Summit | D3: 800 Ticket Sales (Cumulative) | E3: Vishvani | F3: Utkarsh, Pooja | H3: Marketing, Editorial | I3: Nityam, Bhavika | J3: In Progress | K3: 0.7
B4: D2C Summit | D4: Who Gets In Campaign | E4: Nityam | F4: Utkarsh | H4: Marketing | J4: In Progress | K4: 0.5
B5: D2CX Converge | D5: 700 Applications | E5: Arminder | F5: Utkarsh, Pooja | H5: Marketing, BL | I5: Arminder | J5: On Track | K5: 1
B6: D2C Retreat | D6: 50 Applications | E6: Vishvani | F6: Utkarsh, Pooja | H6: Marketing, Editorial | I6: Nityam, Animesh | J6: In Progress | K6: 0.5
B7: FAST42 | D7: Marketing Launch | E7: Nityam | F7: Utkarsh, Pooja | H7: Marketing, BL | I7: Vishvani, Bhavika | J7: Delayed
B8: IP Infra | D8: AI-Led Systems for IP Marketing | E8: Nityam | F8: Utkarsh | H8: Marketing | I8: Nityam, Bhavika, Animesh | J8: Delayed
A10: Media | B10: Media
B11: Brand | C11: Brand v2 Rollout | D11: Rollout Messaging v2 Across All Touchpoints | E11: Nityam | F11: Utkarsh | H11: Marketing, Design | I11: Nityam, Animesh | J11: Delayed | K11: 0.5
B12: Social | C12: Inc42 Social Growth | D12: 220K monthly interactions · LI first formats | E12: Arminder | F12: Utkarsh, Pooja | H12: Marketing, Design | I12: Arminder, Tanya, Ananya | J12: Completed | K12: 1
B13: Acquisition | C13: Acquisition + WEIU (NS2) | D13: Rollout Onsite Acquisition v2 Deploy CLM/onboarding for all touchpoints Establish reporting for WEIU & complete funnel | E13: Nityam | F13: Utkarsh, Tech | H13: Marketing, Tech | I13: Nityam, Animesh | J13: Delayed | K13: 0.5
B14: Video | C14: Event-Led Pipeline | D14: 3 videos/week · 500k+ views & 10K+ interactions | E14: Aditya | F14: Utkarsh, Pooja | H14: Video, Marketing | I14: Tejas, Aditya, Video Team | J14: In Progress | K14: 0.57
B15: Video | C15: Original Short Format | D15: 3 IPs - D2C, Deeptech, News + Trend Based | E15: Aditya | F15: Utkarsh, Pooja | H15: Video, Marketing | I15: Tejas, Aditya, Video Team | J15: In Progress | K15: 0.25
B16: Reports | C16: H1 Funding Report | D16: 2K+ downloads/registrations on Reports | E16: Arminder | F16: Utkarsh, Pooja | H16: Research, Marketing | I16: Sandeep, Arminder, Animesh | J16: In Progress | K16: 0.25
B17: Datalabs | C17: Datalabs Campaign | D17: Source Kya Hai Campaign Launch | E17: Nityam | F17: Utkarsh | H17: Marketing, Datalabs | I17: Bhavika | J17: Delayed
B18: Datalabs | C18: Datalabs Activation & Retention | D18: Lifecycle Flows Bi-Weekly Digests Reactivation Campaign (1 Sequence + 2 EDMs) Watchlist + Alerts (TBD) | E18: Bhavika | F18: Utkarsh | H18: Marketing, Datalabs | I18: Data, Tech | J18: In Progress | K18: 0.3
B19: Datalabs | C19: Datalabs SEO/AEO Expansion | D19: Audit & Improve SEO/AEO for Datalabs - SEO & AEO Phase 3 - Listicles Revamp & Crack Programmatic SEO/AEO via Listicles | E19: Ashish, Prapti | F19: Utkarsh | H19: Tech, Marketing | I19: Tech, Data | J19: In Progress | K19: 0.5
B20: Datalabs | C20: Ask Datalabs | D20: Latency <10 sec Tracking & Feedback Loop | E20: Alistin, Ashish | F20: Utkarsh | H20: Tech, Marketing | I20: Tech, Data | J20: In Progress | K20: 0.5
B21: App | C21: Inc42 App v1 GTM | D21: 5k+ Activated Users Ask Inc42 Social Intelligence Feed | E21: Ranjith, Ashish | F21: Utkarsh | H21: Tech, Marketing, Data | I21: Tech, Data | J21: In Progress | K21: 0.5
B22: Data | C22: DCI / DFI / DAI Quality | D22: 95% DCI/DFI/DAI for funded companies | E22: Prapti | F22: Utkarsh, Tech | H22: Tech, Data | I22: Tech, Prapti, Data Team | J22: Completed | K22: 1
B23: Data | C23: Trend-Based Early-Stage Startups | D23: 500 trend-based & high-value early-stage startups added | E23: Prapti | F23: Utkarsh, Tech | H23: Tech, Data | I23: Tech, Prapti, Data Team | J23: In Progress | K23: 0.5
B24: Data | C24: Investor Database Expansion | D24: 1K new investors from existing DB | E24: Prapti | F24: Utkarsh, Tech | H24: Tech, Data | I24: Tech, Prapti, Data Team | J24: Completed | K24: 1
B25: AI | C25: Social Intelligence Data | D25: Internal AI – Editorial & Social Content Suggestions | E25: Prapti | F25: Utkarsh | H25: Data, Tech | I25: Data Team, Tech | J25: Completed | K25: 1
B26: AI | C26: Internal AI Tools — AI Data Requests + AI Research | D26: AI Data Requests pilot + AI Research on Inc42 Data pilot | E26: Prapti | F26: Utkarsh, Tech | H26: Tech, Data, Editorial | I26: Tech, Data | J26: Delayed
B27: Infra | C27: Data Warehouse | D27: Data Warehouse + Unified User Data with Reverse-ETL — Phase 2 | E27: Prapti | F27: Utkarsh, Tech | H27: Tech, Data | I27: Tech, Prapti, Data Team | J27: In Progress | K27: 0.6
B28: Infra | C28: Analytics & Instrumentation Audit | D28: GA4 + PostHog + Customer.io audit & fixes | E28: Animesh | F28: Utkarsh, Tech | H28: Data, Marketing, Tech | I28: Data, Marketing, Tech | J28: In Progress | K28: 0.3
B29: Infra | C29: Newsletters | D29: Automate All Weekly Newsletters | E29: Animesh | F29: Utkarsh, Tech, Nityam | H29: Tech, Editorial | I29: Tech, Data | J29: On Track | K29: 0.5

Sheet July Sprint
A1: Inc42 Sprint July 2026
A2: Bucket | B2: Sub-Bucket | C2: Goal | D2: People Involved | E2: Founders Involved | F2: Owner | G2: Progress Status | H2: Subjective Summary | I2: Links | J2: Bottleneck | K2: Completion %
A3: Videos | B3: Video Series | C3: Deeptech [Insta First] | D3: Aditya Video Team Editorial | E3: Utkarsh Pooja | F3: Aditya | G3: 50% Or Less | K3: =IFERROR(VLOOKUP(TRIM(G3),Calc!$A$6:$B$11,2,FALSE),"")
A4: Videos | B4: Video Series | C4: D2C [Insta First] | D4: Nityam Vishwani Aditya + Video Team | E4: Utkarsh Pooja | F4: Aditya | G4: 50% Or Less | K4: =IFERROR(VLOOKUP(TRIM(G4),Calc!$A$6:$B$11,2,FALSE),"")
A5: Videos | B5: Video Series | C5: Trends [YouTube First] | D5: Bismah Aditya + Video Team | E5: Utkarsh Pooja | F5: Aditya | G5: 25% Or Less | K5: =IFERROR(VLOOKUP(TRIM(G5),Calc!$A$6:$B$11,2,FALSE),"")
A6: IPs | B6: DRS 2026 | C6: Close 30 Speakers Overall | D6: Palak Agarwal Anshika | E6: Pooja | F6: Palak | G6: 25% Or Less | K6: =IFERROR(VLOOKUP(TRIM(G6),Calc!$A$6:$B$11,2,FALSE),"")
A7: IPs | B7: DRS 2026 | C7: Paid Confirmed Attendees - 200 | D7: Nityam Vishwani Bhavika Sakshi | E7: Utkarsh | F7: Vishwani | G7: 75% Or Less | K7: =IFERROR(VLOOKUP(TRIM(G7),Calc!$A$6:$B$11,2,FALSE),"")
A8: IPs | B8: DRS 2026 | C8: 50 Free Attendees | D8: Sakshi | E8: Pooja | F8: Sakshi | G8: Yet to start | K8: =IFERROR(VLOOKUP(TRIM(G8),Calc!$A$6:$B$11,2,FALSE),"")
A9: IPs | B9: DRS 2026 | C9: DRS Who Get's In Campaign Launch + Influencer Amplification | D9: Vishwani Nityam | E9: Utkarsh | F9: Nityam | G9: 25% Or Less | K9: =IFERROR(VLOOKUP(TRIM(G9),Calc!$A$6:$B$11,2,FALSE),"")
A10: IPs | B10: D2C Retreat | C10: Website & Marketing Launch | D10: Marketing | E10: Utkarsh | G10: Completed | K10: =IFERROR(VLOOKUP(TRIM(G10),Calc!$A$6:$B$11,2,FALSE),"")
A11: IPs | B11: D2C Retreat | C11: Confirm 10 Attendees | D11: Yash Nitika | E11: Pooja Vaibhav | F11: Yash | G11: 50% Or Less | K11: =IFERROR(VLOOKUP(TRIM(G11),Calc!$A$6:$B$11,2,FALSE),"")
A12: Editorial | B12: Series Launch | C12: Business Model Breakdown Series Launch | D12: Meha Palak Sharma | E12: Pooja | F12: Meha | G12: Completed | K12: =IFERROR(VLOOKUP(TRIM(G12),Calc!$A$6:$B$11,2,FALSE),"")
A13: Editorial | B13: Exclusives | C13: 10 Exclusives | D13: Editorial | E13: Pooja | F13: Vinay | G13: Completed | K13: =IFERROR(VLOOKUP(TRIM(G13),Calc!$A$6:$B$11,2,FALSE),"")
A14: Editorial | B14: Report Design | C14: Automate Report Design With Claude | D14: Sandeep | E14: Pooja Utkarsh | F14: Sandeep | G14: Completed | K14: =IFERROR(VLOOKUP(TRIM(G14),Calc!$A$6:$B$11,2,FALSE),"")
A15: Courses | B15: RetailX | C15: Lock Curriculum & Concept Note | D15: Shantanu | E15: Utkarsh Pooja | F15: Shantanu | G15: Almost 100% | K15: =IFERROR(VLOOKUP(TRIM(G15),Calc!$A$6:$B$11,2,FALSE),"")
A16: Courses | B16: RetailX | C16: Lock 3 Speakers + 10 Brand Names | D16: Shantanu Palak Agarwal Anshika | E16: Pooja | F16: Palak | G16: 25% Or Less | K16: =IFERROR(VLOOKUP(TRIM(G16),Calc!$A$6:$B$11,2,FALSE),"")
A17: Courses | B17: RetailX | C17: Brand Identity + Website Brief Lock | D17: Shantanu | E17: Utkarsh | F17: Shantanu | G17: 25% Or Less | K17: =IFERROR(VLOOKUP(TRIM(G17),Calc!$A$6:$B$11,2,FALSE),"")
A18: AI | B18: Internal AI Tools | C18: News AI & Markets AI Final Adoption | D18: Editorial | E18: Utkarsh Pooja | F18: Nikhil | G18: Completed | K18: =IFERROR(VLOOKUP(TRIM(G18),Calc!$A$6:$B$11,2,FALSE),"")
A19: AI | B19: Internal AI Tools | C19: Social & Editorial Ideas Pipeline Agent Launch & Adoption | D19: Nikhil Shishir Vinay Akshit Meha Prapti Tanuj Sandeep | E19: Utkarsh Pooja | F19: Prapti | G19: Completed | K19: =IFERROR(VLOOKUP(TRIM(G19),Calc!$A$6:$B$11,2,FALSE),"")
A20: AI | B20: Internal AI Tools | C20: Editorial Stories Feedback Agent Launch & Adoption | D20: Nikhil Shishir Vinay Akshit Meha Prapti Tanuj Sandeep | E20: Utkarsh Pooja | F20: Prapti | G20: Completed | K20: =IFERROR(VLOOKUP(TRIM(G20),Calc!$A$6:$B$11,2,FALSE),"")
A21: Brand | B21: Brand Refresh | C21: Inc42 Brand v2 Rollout Across All Touchpoints | D21: Nityam Animesh | E21: Utkarsh | F21: Nityam | G21: 75% Or Less | K21: =IFERROR(VLOOKUP(TRIM(G21),Calc!$A$6:$B$11,2,FALSE),"")
A22: Product & Marketing | B22: App | C22: Inc42 App (Ready To Go Live) | D22: Product & Tech | E22: Utkarsh | F22: Ranjith | G22: 75% Or Less | K22: =IFERROR(VLOOKUP(TRIM(G22),Calc!$A$6:$B$11,2,FALSE),"")
... A27: HR | B27: Hiring | C27: Sr. Visual Designer | D27: HR | E27: Utkarsh | F27: Shweta | G27: 75% Or Less | K27: =IFERROR(VLOOKUP(TRIM(G27),Calc!$A$6:$B$11,2,FALSE),"")

Sheet Aug MOP
A1: Area | B1: Bucket | C1: Sub Bucket | D1: Goals | E1: Accountability | F1: Consulted | G1: Deadline | H1: Divisions Involved | I1: Team Members Involved | J1: Completion Status | K1: Progress (%) | L1: Comments/Bottlenecks
A2: IPs | B2: IPs
B3: D2C Summit | D3: 900 Ticket Sales (Cumulative) | E3: Vishvani | F3: Utkarsh, Pooja | G3: 46252 | H3: Marketing, Editorial | I3: Nityam, Bhavika | J3: In Progress
B4: D2C Summit | D4: Who Gets In Campaign | E4: Nityam | F4: Utkarsh | G4: 46249 | H4: Marketing, Social | I4: Vishvani | J4: On Track
B5: D2CX Converge | D5: 700 Applications | E5: Arminder | F5: Utkarsh, Pooja | G5: 46265 | H5: Marketing, BL, Social | I5: Animesh | J5: On Track
B6: D2C Retreat | D6: 30 Qualified Applications | E6: Vishvani | F6: Utkarsh, Pooja | G6: 46265 | H6: Marketing, Editorial | I6: Nityam, Animesh | J6: In Progress
B7: CTO Summit | D7: Marketing Launch & 75 Ticket Sales | E7: Vishvani | F7: Utkarsh, Pooja | G7: 46265 | H7: Marketing, Editorial | I7: Nityam, Bhavika | J7: In Progress
A9: Media | B9: Media
B10: Brand | C10: Brand v2 Rollout | D10: Rollout Messaging v2 Across All Touchpoints | E10: Nityam | F10: Utkarsh | G10: 46265 | H10: Marketing, Design | I10: Nityam, Animesh | J10: Yet To Start
B11: Social | C11: Inc42 Social Growth | D11: 242K Monthly Interactions · 4 Recurring Series · ORM Tool + 90% Response Rates | E11: Arminder | F11: Utkarsh, Pooja | G11: 46265 | H11: Marketing, Design | I11: Arminder, Tanya, Shivanshi | J11: In Progress
B12: Acquisition | C12: Acquisition + WEIU (NS2) | D12: Rollout Onsite Acquisition v2 Establish reporting for WEIU & complete funnel | E12: Nityam, Prapti | F12: Utkarsh, Tech | G12: 46265 | H12: Marketing, Tech | I12: Nityam, Animesh | J12: Yet To Start
B13: Video | C13: Event-Led Pipeline | D13: 3 videos/week · 500k+ views & 5K+ interactions | E13: Aditya | F13: Utkarsh, Pooja | G13: 46265 | H13: Video, Marketing | I13: Video Team | J13: In Progress
B14: Video | C14: Original Short Format | D14: 2 videos/week D2C Series 1 video/week YT Series (10 min+) 200k+ views & 2K+ interactions | E14: Aditya | F14: Utkarsh, Pooja | G14: 46265 | H14: Video, Marketing | I14: Video Team | J14: In Progress
B15: Reports | C15: Report | D15: 1K+ downloads/registrations on Reports | E15: Arminder | F15: Utkarsh, Pooja | G15: 46265 | H15: Research, Marketing | I15: Sandeep, Arminder, Animesh | J15: Yet To Start
B16: Datalabs | C16: Datalabs Activation & Retention | D16: Lifecycle Flows Bi-Weekly Digests Reactivation Campaign (1 Sequence + 2 EDMs) | E16: Bhavika | F16: Utkarsh | G16: 46265 | H16: Marketing, Datalabs | I16: Data, Tech | J16: In Progress
B17: Datalabs | C17: Datalabs SEO/AEO Expansion | D17: Audit & Improve SEO/AEO for Datalabs - SEO & AEO Phase 3 - Listicles Revamp & Crack Programmatic SEO/AEO via Listicles | E17: Prapti | F17: Utkarsh, Ashish | G17: 46259 | H17: Tech, Marketing | I17: Tech, Data | J17: In Progress
B18: Datalabs | C18: Payment & Dunning Systems | D18: Dunning, Payment Retry, Payment URLs for Recovery & Abandons | E18: Ashish | F18: Utkarsh | G18: 46255 | H18: Tech | J18: In Progress
B19: Datalabs | C19: Ask Datalabs | D19: Latency <10 sec Streaming, Fast Mode Tracking, Analytics & Feedback Loop | E19: Ranjith, Ashish | F19: Utkarsh | G19: 46255 | H19: Tech, Marketing | I19: Tech, Data | J19: In Progress
B20: App | C20: Inc42 App v1 GTM | D20: 1k+ Activated Users Ask Inc42 Social Intelligence Brief 50+ User Interviews & Feedbacks | E20: Ranjith | F20: Utkarsh | G20: 46265 | H20: Tech, Marketing, Data | I20: Tech, Marketing, Data | J20: In Progress
B21: Data | C21: Trend-Based Early-Stage Startups | D21: 500 trend-based & high-value early-stage startups added | E21: Prapti | F21: Utkarsh, Tech | G21: 46265 | H21: Data | I21: Data | J21: In Progress
B22: Data | C22: Investor Database Expansion | D22: 1K new investors from existing DB | E22: Prapti | F22: Utkarsh, Tech | G22: 46265 | H22: Data | I22: Data | J22: In Progress
B23: AI | C23: Social Intelligence Data | D23: Make Social Intelligence Data Queryable via Slack Company-Wide | E23: Prapti | F23: Utkarsh | G23: 46255 | H23: Data | I23: Tech, Data | J23: In Progress
B24: AI | C24: Internal AI Tools — AI Data Requests + AI Research | D24: AI Data Requests pilot + AI Research on Inc42 Data pilot | E24: Prapti | F24: Utkarsh, Tech | G24: 46265 | H24: Tech, Data, Editorial | I24: Tech, Data | J24: Yet To Start
B25: Infra | C25: Data Warehouse | D25: Data Warehouse + Unified User Data + Event Analytics with Reverse-ETL Deployed | E25: Prapti | F25: Utkarsh, Tech | G25: 46265 | H25: Tech, Data | I25: Tech, Prapti, Data Team | J25: In Progress
B26: Infra | C26: Server & Cost Optimisation | D26: Migrate & consolidate all servers/systems to Azure and optimise cost by 30% | E26: Ashish | F26: Utkarsh | G26: 46265 | H26: Tech | I26: Tech | J26: In Progress
B27: Infra | C27: Analytics & Instrumentation Fixes | D27: GA4 + PostHog + Customer.io audit & fixes | E27: Bhavika, Animesh | F27: Utkarsh, Tech, Data | G27: 46265 | H27: Data, Marketing, Tech | I27: Data, Marketing, Tech | J27: In Progress
B28: Infra | C28: Newsletters | D28: Automate All Weekly Newsletters | E28: Animesh | F28: Utkarsh, Tech, Nityam | G28: 46265 | H28: Tech, Editorial | I28: Tech, Data | J28: In Progress

Sheet FY27 Plan — Engines × Tracks
A1: FY27 Plan — Engines × Tracks
A2: One horizon plan · LOCKED 2026-08-21 (Utkarsh): O2 Audience runs on the strategy's engine verbs — Acquire & Identify → Activate & Deepen → Retain & Renew — journey stages of one person across all surfaces; per-product work lives in the MOP, serving a stage. Lanes match the Sept MOP.
A4: Track | B4: What it means in plain terms | C4: Owner | D4: Waits on | E4: Aug | F4: Sep | G4: Oct | H4: Nov | I4: Dec | J4: Jan | K4: Feb | L4: Mar
A5: NEWSROOM – upstream of all three engines
A6: Newsroom | B6: Journalism powers all three engines and answers to none – the trust everything borrows | C6: Editorial | D6: – independent | E6: ● Operating model adopted – editorial placed upstream, interfaces named | F6: ◐ Editorial Feedback Loop restarted | G6: ● METRIC DECIDED – return-attribution vs parked R30 (habit line) + citations (authority line) vs others | I6: ◇ | J6: ◇ | K6: ◇ | L6: ◇
A7: O1 · BRAND & DISTRIBUTION
A8: Brand & Campaigns | B8: One Inc42 message, told the same way everywhere | C8: Nityam | D8: – | E8: ● Brand v2 rollout starts – agreement done, work can begin | F8: ● Message live across Inc42 media ● Extend to Datalabs and the App, not just media ● Perception survey sent ● Inc42 Design System v1 ● IP Design System | G8: ● One message across all three services ● Read the perception baseline ● Inc42 master brand campaign work kickoff ● Design refresh & unification work kickoff ● Founder branding kickoff with positioning & calendar ● Employer branding kickoff | H8: ● Inc42 master brand campaign work ● Design refresh & unification work ● Founder branding ● Employer branding | I8: ● Year in Review ships ● Inc42 master brand campaign work ● Design refresh & unification work ● Founder branding ● Employer branding | J8: ● Outlook 2027 ships | K8: ◇ | L8: ◇
A9: Social | B9: The engine's daily reach – handles, platforms, series. Voice: raw, authentic, personality, aspiration | C9: Arminder | D9: – | E9: ● 242K monthly interactions ● 4 Series ● ORM Tool Locked | F9: ● Series shipping on the owner grid ● Expand focus to Twitter and Facebook ● ORM at 90% reply rate | G9: ● Cadence holds ● ORM at 100% reply rate | H9: ● Cadence holds | I9: ◇ | J9: ◇ | K9: ◇ | L9: ◇
A10: Video | B10: Explainers, news roundups/show, series & flagship – the seam between newsroom and brand | C10: Aditya | D10: – | E10: ● D2C Reels IP at 2x/week ● Youtube Explainer Series at 1x/week | F10: ● 500k+ views/m, 5k+ Interactions ● D2C Reels IP at 2x/week ● 2 New Reels IP Piloted ● Youtube Cadence Solidified | G10: ● Existing cadence continues (3 Reel IPs, 1 YT IP) ● 1 New YT IP Kickoff ● Flagship video IP/podcast work kickoff | H10: ● 1Mn+ views/m, 10k+ Interactions ● Existing Cadence continues ● Flagship video IP launch | I10: ◇ | J10: ◇ | K10: ◇ | L10: ◇
A11: Distribution | B11: The multiplier on everything above – influencer, amplification, UGC, citations | C11: Nityam | D11: Citations instrumentation | E11: ▢ Scope | F11: ● Citations tracking starts – feeds the perception KPI | G11: ◇ Influencer & amplification playbook from what Brand v2 shows | H11: ◇ | I11: ◇ | J11: ◇ | K11: ◇ | L11: ◇
A12: O2 · AUDIENCE
A13: Measurement & Data Activation | B13: See the audience properly, fix what we cannot see – and USE what we already know without waiting for the rest | C13: Prapti (warehouse & data activation) · Ranjith (instruments) | D13: Data Activation waits on NOTHING – that is the point. Measurement waits on the 30-day clock (product) | E13: ● Record when our tracking broke, so trends stop lying ● Clean up duplicate and dead data ● Pipe app activity into the warehouse – recovers 3 activity types at once 🔴 ● Onboarding (seniority + company) at APP SIGN-IN (not signup – 3 in 4 app users already have an account) ● Fix and set audit process for all analytics (events, properties) across Inc42, Datalabs, App, IPs ● Fix reading-depth (scroll) tracking ● Fix duplicate-person merging in the app ● Do-not-contact and safety rules in place ● Agree which fields we push and who depends on them ● First Reverse ETL push live | F13: ● One profile per person across web, data, email and app ● Turn on the Datalabs 30-day counter – recovers a whole activity type ● Day-by-day view of what each person did ● NORTH STAR MEASURABLE PROPERLY for the first time ● Tracking changeover completes (~20 Sep) ◇ Product picks what to build from what engagement data shows ● Restart contact with 93,000 dormant reachable people ● Push the engagement tier into the messaging tool ● Segments built on engagement score go live | G13: ● See who uses more than one product ● Build the engagement score on real data ● Set the engagement tiers from evidence, not opinion ◇ Product picks what to build from what engagement data shows ● Full behavioural targeting | H13: ◇ | I13: ◇ | J13: ◇ | K13: ◇ | L13: ◇
A14: Unification | B14: Making Inc42 feel like one product instead of five separate ones | C14: Utkarsh (chair) → Ranjith at delivery Nityam owns the brand/messaging half | D14: Identity spine (Sep, Engine tab) | E14: ● Agree what "One Inc42" actually means – the seam decision nobody owns today ● Write it down: one login, one navigation, one value proposition – a dated document, not a discussion ● Audit where the three services contradict each other today ● Lifecycle journeys ship for Datalabs and the App SEPARATELY (unification comes after, by design) | F14: ● UNIFICATION PLAN shipped – one design for messaging, navigation, onboarding and lifecycle journeys across Inc42, Datalabs, App (plan in Sept, delivery phased) ● Cross-surface use measurable for the first time (1.6–3.4% today) | G14: ● Hands over to Ranjith for delivery ◇ Which cross-surface paths to build next, from what people actually use | H14: ◇ | I14: ◇ | J14: ◇ | K14: ◇ | L14: ◇
A15: Acquire & Identify | B15: Do the right people ARRIVE — and do we learn who they are at the door? One person, any surface | C15: Growth + Ranjith (gates & capture) · Nityam (acquisition) | D15: App sign-in capture (Aug) | E15: ● App is live (12 Aug) ● Marketing ramp begins w/c 25 Aug ▶ ● Seniority + company asked at app sign-in ⚠ Web acquisition goal still targets WEIU – needs rewriting | F15: ● App marketing at full scale ◐ Sign-up gate test on web (onsite freewall & newsletter locks) ● ONE onboarding pattern agreed across all three services | G15: ◇ Product picks what to change from what the gate test shows | H15: ◇ | I15: ◇ | J15: ◇ | K15: ◇ | L15: ● Signup→identified conversion read (the stage's number)
A16: Activate & Deepen | B16: Does a known person form a HABIT in the first weeks — and reach a second surface? The mechanism competition runs INSIDE this stage: candidates compete on 30-day return, winners get investment, losers get dropped | C16: Ranjith (runs) · Utkarsh (scores) | D16: Engagement scoring (Oct, Measurement track) | E16: ● App notifications for Brief & Breaking cadence ● Datalabs Newsletter · Social Briefing (Pulse) – candidates named ▶ ● Lifecycle journeys ship for Datalabs and the App SEPARATELY | F16: ● Alerts, community and report surfaces scoped ● Unification plan folds the journeys into one design (with the Unification track) | G16: ● FIRST SCORING – every candidate measured on 30-day return, on real data ● Journeys running on real engagement segments | H16: ● Winners get investment, losers dropped – visibly, so the discipline is real | I16: ● Winners become the membership's candidate entitlements | J16: ◇ Second round | K16: ◇ | L16: ● Persistence read – did the 34%→94.5% frequency yardstick move?
A17: Retain & Renew | B17: MONTHS later, are they still here — and did we ask them to stay? Reactivation, win-backs, renewal, payment recovery | C17: Ranjith (renewal + in-product) · Animesh (campaigns) | D17: First warehouse push (Aug) + segments (Sep) | E17: ▶ ● Payment retries and dunning – recovers failed payments | F17: ▶ ● Reactivation sequence to the 93K dormant reachable pool ● Datalabs renewal motion, Plus new & existing memberships call | G17: ● Win-backs running on engagement segments | H17: ◇ | I17: ◇ | J17: ◇ | K17: ◇ | L17: ● Renewal rate read vs today's 15%
A18: AI Layer (Ask) | B18: Ask Inc42 – answers drawn from our own data, on every surface | C18: Ranjith + Ashish | D18: – nothing. Already shipping | E18: ▶ ● Ask Datalabs: streaming and fast mode ship (21 Aug) ▶ ● Ask Inc42 live in the app | F18: ● Decide whether Ask goes on Inc42.com, and build it ● Start counting Ask queries – one of only two audience activities we cannot currently see at all | G18: ● Ask live on all three surfaces ● Usage and answer quality measured | H18: ◇ Does the AI layer sit inside the paid membership or stay free – decided on usage, not opinion | I18: ◇ | J18: ◇ | K18: ◇ | L18: ◇
A19: Offering | B19: Learning what people would actually pay for, before we build it | C19: Ranjith + Utkarsh | D19: Engagement evidence (Oct) + A1 probe | F19: ● Price probe on existing subscribers ◇ Read the probe | G19: ◐ Engagement evidence builds up | H19: ◇ Shape the offering from what people actually use | I19: ◇ Define the membership candidate | J19: ◇ Design the pilot | K19: ◇ | L19: ◇ Pilot runs early FY28
A20: O3 · IPs, EVENTS & COMMUNITIES
A21: Flagships & Editions | B21: Which rooms land when – milestones only; the IP calendar tab stays the source of truth | C21: Per-IP owners | D21: IP calendar | E21: ● D2C Summit delivered (19 Aug) | F21: ● CTO Summit (30 Sept) · D2C Retreat (17–19 Sept) | G21: ● FAST42 marketing starts | H21: ● AI Workplaces launch | I21: ◇ | J21: ◇ | K21: ● FAST42 event · Tech Rich List | L21: ◇
A22: Cohorts & Communities | B22: Do the recurring formats compound – cohorts, dialogues, the club cadence | C22: Per-IP owners | D22: – | E22: ● D2CX C10 starts (Aug end) | F22: ● D2CX C10 starts (Aug end) ● Convocation 22–23 Sept | G22: ● Basecamp 3–5 Oct ● RetailX C1 Starts | H22: ◐ C11 starts (Nov end) | I22: ◇ Dialogues cadence read | J22: ◇ | K22: ◐ C12 starts (Feb mid) | L22: ◇
A23: IP Capability | B23: Does the portfolio get the machinery – QAA, per-edition P&L, the per-IP-GM model | C23: Per-IP owners · Utkarsh (QAA rule) | D23: Events-team sheets (the QAA instrument) | E23: ● QAA adopted – same qualification bar as QIA, never a second definition ● Events-sheets ask scoped: which events, which columns, who sends · CTO Summit + D2CX Convocation + Retreats delivered (Sept MOP) | F23: ● AI Led IP Marketing System (Brand, Comms, Outreach, Analysis, etc) | G23: ◇ | H23: ◇ | I23: ◇ | J23: ◇ | K23: ● FAST42 event (Feb) | L23: ◇ QAA in every edition report
A24: O4 · ENGINE ROOM
A25: Internal AI & Agent Platform | B25: The AI that runs the company – pilots, adoption, the agent platform. A11: cost per QIA roughly flat while QIA scales | C25: Prapti (pilots) · Ranjith (platform, per S5) | D25: QIA measurable (~Oct) for the cost line | E25: ▶ ● Social intelligence queryable via Slack | F25: ● AI Data Requests + AI Research pilots live | G25: ● Adoption push toward the 20–30-user mandate · cost-per-QIA baseline (first measurable month) | H25: ◐ Cost line reported monthly | I25: ◇ | J25: ◇ | K25: ◇ | L25: ● A11 read: cost flat while QIA multiplied?
A26: Automation & Infra | B26: The boring compounding – automation, templates, the design system, the servers | C26: Animesh · Ashish · Akshay (design system) | D26: – | E26: ▶ ● Newsletter automation · Azure migration in flight | F26: ● Invoicing & Support automation · ≥2 repeat formats templated ● Server migrations close-out + cost stabalisation | G26: ◇ Next automation targets from ops pain | H26: ◇ | I26: ◇ | J26: ◇ | K26: ◇ | L26: ● Cost base read vs Aug
A28: NOTES — carried forward from the pre-lock plan
A29: 1. CROSSWALK to the MOP: lanes match 1:1. In O2, MOP rows are SURFACES (App, Datalabs, Data…) serving journey-stage tracks — read the Serves column; one surface may serve different stages in different months. Every MOP Serves value must name a track here; the Monday serves-check enforces both directions.
A30: 2. ▶ marks work already running as a MOP goal — this tab gives it a destination, it is not new work landing on top.
A31: 3. 🔴 We currently compute the north-star on 3 of its 9 defined activities; most of the rest are already tracked and just not piped into the warehouse. WHEN THOSE SWITCH ON THE NUMBER WILL JUMP — that is a measurement fix, NOT growth, and must not be banked as growth.
A32: 4. The app launched 12 Aug. Three in four app users are existing accounts signing IN — so capture happens at sign-in, not signup. The 30-day tracking changeover is calendar time: started in Aug it clears ~20 Sep; later, everything after moves with it.
A33: 5. Unification is chaired (Utkarsh) because it cuts across product, brand, Datalabs and the app — it graduates to Ranjith once "One Inc42" is defined in writing. The mechanism competition inside Activate & Deepen is a competition, not a delivery plan: evidence decides which survive.
A34: 6. ⚠ marks known-stale items left visible on purpose (e.g. the web acquisition goal still citing a retired metric) — fixed at the MOP review, not silently here.
A35: 7. Lanes have opposite shapes on purpose: Audience lands by ~Oct then runs; Brand / IP / Engine Room fill as evidence arrives. Newsroom and IP lanes are thin BY DESIGN — first horizon entries, not incomplete plans.
A36: 8. Griffin is out of scope on this plan and the MOP (Utkarsh, 2026-08-21) — it runs on the Griffin desk with its own cadence.
A38: WHAT WE DELIBERATELY HAVE NOT DECIDED YET (merged register – single source)
A39: Decision | B39: Who decides | C39: When | D39: What tells us the answer
A40: What "One Inc42" actually means in the product | B40: Utkarsh | C40: Sep | D40: A written definition – that document IS the deliverable, not a meeting
A41: Who owns unification after October | B41: Utkarsh | C41: Oct retro | D41: Whether "One Inc42" is defined in writing and the August instrument work has landed — then delivery moves to product
A42: Which retention mechanisms survive → get investment | B42: Utkarsh scores (Oct) · Ranjith invests (Nov) | C42: Oct → Nov | D42: 30-day return lift – measured, not argued
A43: What the membership contains | B43: Ranjith + Utkarsh | C43: Dec | D43: What engaged people actually use, not what we assume
...

Sheet Sept MOP
A1: SEPT MOP — RATIFIED & LOCKED 2026-08-21 (Utkarsh). Lanes = the FY27 Plan lanes; every row's Serves resolves to a track there (serves-check runs Mondays 09:40). Griffin out of scope here — tracked on the Griffin desk.
A2: Lane | B2: Bucket | C2: Goals | D2: Accountability | E2: Consulted | F2: Deadline | G2: Serves | H2: Notes / provenance
A3: NEWSROOM (upstream of all three engines)
A4: NR | B4: Editorial | C4: (existing editorial cadence rows carry as-is) | D4: Editorial | E4: Utkarsh | F4: 30 Sept | G4: Newsroom → Audience interface (the return reason) | H4: Editorial metric decision lands ~Oct with the scoring work — no metric row until then
A5: O1 · BRAND & DISTRIBUTION
A6: O1 | B6: Brand | C6: 2 brand campaigns shipped · recall measured against the JAS baseline · Brand v2 message live across Inc42 media + extended to Datalabs & App | D6: Nityam | E6: Utkarsh | F6: 30 Sept | G6: Brand & Distribution · Brand & Campaigns | H6: OND focus IS brand (no new IP launches). Extension to all three services per the Product & Brand tab
A7: O1 | B7: Social | C7: Monthly interactions target (rebaseline post-Aug) · series shipping on the owner grid | D7: Arminder | E7: Utkarsh, Pooja | F7: 30 Sept | G7: Brand & Distribution · Social | H7: Carry: series owners+dates were overdue in Aug
A8: O1 | B8: Video | C8: Per the video plan — ⚠ REBUILD FIRST: draft is built around departed Tejas; Aditya interim. Owner set 08-21: Aditya | D8: Aditya | E8: Utkarsh | F8: 30 Sept | G8: Brand & Distribution · Video
A9: O1 | B9: Campaigns | C9: Perception survey SENT — overdue since July (the brand vision's own Q2 gate) | D9: Nityam | E9: Utkarsh | F9: 15 Sept | G9: Brand & Distribution · Brand & Campaigns | H9: NEW from the Product & Brand tab — the T0 for every brand read
A10: O2 · AUDIENCE
A11: O2 | B11: Measurement | C11: Identity spine live (web+Datalabs+email+app leg) · Datalabs 30-day counter ON · app events piped · NORTH STAR PROPERLY MEASURABLE | D11: Prapti (data/warehouse) · Ranjith (implementation) | E11: Utkarsh | F11: per roadmap v2 Wave 1–2 | G11: Audience · Measurement & Data Activation | H11: REWRITTEN from the 08-12 draft: baseline is DONE (pulled+verified 08-14/15); owner updated per the warehouse ownership decision (was Nityam+Prapti). Dates from 62-warehouse-roadmap-v2.md
A12: O2 | B12: Unification | C12: "One Inc42" WRITTEN DEFINITION shipped — one login, one navigation, one value proposition; the document IS the deliverable | D12: Utkarsh (chair) | E12: Ranjith, Nityam | F12: 30 Sept | G12: Audience · Unification | H12: NEW — the Sept gate for unification's graduation to Ranjith (Oct retro). Was in the AOP plan, missing here
A13: O2 | B13: Activation | C13: First reverse-ETL push LIVE — 26K qualified reachable by role · reactivation sequence to the 93K dormant pool · engagement tier pushed to Customer.io | D13: Prapti + Growth | E13: Utkarsh | F13: 30 Sept | G13: Audience · Measurement & Data Activation | H13: NEW from the Audience Engine tab — was in nobody's September
A14: O2 | B14: Retention | C14: 🔴 RENEWAL MOTION BUILT — 15% auto-renew today; 26–142 Plus terms end monthly with zero communication | D14: Ranjith | E14: Utkarsh | F14: 30 Sept | G14: Audience · Retain & Renew | H14: OWNED 08-21: renewal comms → product (Ranjith), consistent with membership-line ownership. Was the largest unclaimed lever (see tiers workbook §5)
A15: O2 | B15: Acquisition | C15: Onsite acquisition v2 live · qualified signups from bought channels baselined · gate test STARTED (Register Lock restored first) | D15: Nityam (Animesh runs) | E15: Utkarsh | F15: 30 Sept | G15: Audience · Acquire & Identify | H15: The interim lane's first month with a number. Gate test per A2 — holdout needs Register Lock back
A16: O2 | B16: Acquisition | C16: Reports distribution target | D16: Arminder | E16: Utkarsh | F16: 30 Sept | G16: Audience · Acquire & Identify | H16: Moved into O2/Acquisition by Utkarsh 08-21 — reports drive downloads→registrations. Editorial still supplies the report itself (Newsroom interface)
A17: O2 | B17: Datalabs | C17: Lifecycle: campaign sequences live (marketing) · behavioural alerts scoped (product) · Datalabs onboarding DESIGNED (the only service without one) | D17: Animesh · Ranjith | E17: Utkarsh | F17: 30 Sept | G17: Audience · Activate & Deepen | H17: First month under the lifecycle split + onboarding gap from the Product & Brand tab
A18: O2 | B18: Datalabs | C18: Payment leak Sprint 2 close-out + B1 mobile + B2 filters (deferred from Aug) | D18: Ranjith (owner) · Ashish (build) | E18: Utkarsh, Prapti | F18: 30 Sept | G18: Audience · Retain & Renew | H18: Payments → product per the ownership map. Involuntary churn — distinct from the renewal row
A19: O2 | B19: App | C19: Activation target vs the Aug baseline · employer+seniority capture at SIGN-IN live · 30-day tracking clock CLEARS (~20 Sept if started Aug) | D19: Ranjith | E19: Utkarsh | F19: 30 Sept | G19: Audience · Acquire & Identify · coverage | H19: UPDATED: app launched 12 Aug; sign-in outnumbers register 3:1 so capture moves to sign-in; identify() already solved (98.3%)
A20: O2 | B20: AI (Ask) | C20: Ask on Inc42.com DECIDED and building (third surface) · Ask query events instrumented — one of the two genuinely unmeasured qualifying actions | D20: Ranjith · Ashish | E20: Utkarsh | F20: 30 Sept | G20: Audience · AI Layer | H20: SPLIT 08-21 from the O4 AI row — consumer-facing Ask is an Audience capability; Engine Room keeps internal AI only
A21: O2 | B21: Retention Mechanisms | C21: Pulse (social briefing) ENTERS the competition — legal gate closed + the 15-Jul team approval finally sent · candidate list named (alerts, community, report surfaces) | D21: Ranjith (runs) · Utkarsh (scores Oct) | E21: — | F21: 30 Sept | G21: Audience · Activate & Deepen | H21: NEW — the competition's first entrants; scored on 30-day return lift in Oct
A22: O2 | B22: Data | C22: Entity coverage: startups + investors adds (qualification layer) | D22: Prapti | E22: Utkarsh | F22: 30 Sept | G22: Audience · Measurement & Data Activation · coverage
A23: O2 | B23: Offering | C23: A1 price probe RUN + READ on the legacy book (₹4,999–14,999 band, pooled ~20% bar) · ~38 lapsed data-buyers called | D23: Ranjith + Utkarsh | E23: — | F23: 30 Sept | G23: Audience · Offering | H23: NEW — pre-registered bar: sample migrating below ~20% = tier prices rework before anything is built
A24: O3 · IPs, EVENTS & COMMUNITIES
A25: O3 | B25: CTO Summit | C25: Delivered end-to-end 30 Sept — identity, assets, marketing, 75+ tickets, experience | D25: Vishvani (mktg) · Akshay (design) · Pooja (agenda) | E25: Utkarsh | F25: 30 Sept | G25: IPs · Flagships & Editions | H25: Akshay Day-60 outcome; first per-IP-GM-style edition. QAA measurable once events-sheets lane exists
A26: O3 | B26: D2CX | C26: Convocation 22–23 Sept delivered · Basecamp 3–5 Oct prepped | D26: Shantanu | E26: Utkarsh | F26: 23 Sept | G26: IPs · Cohorts & Communities | H26: Mid-VD join is the design cover
A27: O3 | B27: D2C Retreat | C27: Retreat delivered 17–19 Sept · 30 qualified applications closed | D27: Vishvani | E27: Nityam, Utkarsh | F27: 19 Sept | G27: IPs · Flagships & Editions | H27: "Qualified" = the QIA bar — same definition (QAA rule)
A28: O3 | B28: FAST42 | C28: Marketing prep only — launch Oct, event FEB | D28: Nityam | E28: Utkarsh | F28: prep | G28: IPs · Flagships & Editions | H28: Do NOT let a delivery row reappear for Dec
A29: O4 · ENGINE ROOM
A30: O4 | B30: Design system | C30: ≥2 repeat formats templated (T3→template) · pod intake running on the board | D30: Akshay | E30: Utkarsh | F30: 30 Sept | G30: Engine Room · Automation & Infra | H30: The compounding metric
A31: O4 | B31: Automation | C31: Newsletter automation live · invoicing/chat-support automation for IP ops (from Aug) | D31: Animesh · Ashish | E31: Utkarsh | F31: 30 Sept | G31: Engine Room · Automation & Infra
A32: O4 | B32: Infra | C32: Azure migration close-out (if deferred from Aug at the kickoff item) | D32: Ashish | E32: Utkarsh | F32: ⬜ per Aug decision | G32: Engine Room · Automation & Infra | H32: The Aug collision decision decides this row
A33: O4 | B33: AI | C33: Internal-AI pilots — AI Data Requests + AI Research on Inc42 data | D33: Prapti | E33: Utkarsh | F33: 30 Sept | G33: Engine Room · Internal AI & Agent Platform | H33: Prapti-deprioritisation rule holds. Consumer Ask split to the O2 AI (Ask) row
A35: RULES (compact): 1· Protected tier — warehouse/measurement rows: raids are reported misses, not absorbed. 2· Prapti-deprioritisation — if the warehouse gets a date, something else of hers comes OFF. 3· Serves grammar = Engine · Track (· driver where QIA-touching); a row serving nothing is missing strategy or shouldn't exist — control-tower check flags orphans both ways.
A37: O1 | B37: Distribution | C37: Citations tracking starts — feeds the perception KPI | D37: Nityam | E37: Utkarsh | F37: 30 Sept | G37: Brand & Distribution · Distribution | H37: ADDED by the serves-check 08-21: committed in the FY27 plan, served by no row
A38: O3 | B38: IP Capability | C38: Events-team sheets ask scoped — which events, which columns, who sends each cycle (the QAA instrument) | D38: Utkarsh (ask) · events team (supply) | E38: — | F38: 30 Sept | G38: IPs · IP Capability | H38: ADDED by the serves-check 08-21: the QAA instrument's first concrete step
